Workbook

Sheet Application_Ledger
L1: Seller | O1: Buyer
A2: REF NO. | B2: LOA Number | C2: APPLICATION NO. | D2: APPROVAL NO. | E2: SELLER | F2: BUYER | G2: FROM DATE | H2: TO DATE | I2: APPLIED MWH | J2: APPROVED MWH | K2: Schedule MWH | L2: ISTS | M2: Application Fee | N2: RLDC Fee | O2: ISTS | P2: Application Fee | Q2: RLDC Fee
E3: 46113
A4: 154714 | B4: NVVN_Kreate_200MW | C4: SJVN010426WR2354 | D4: WR/2026/41024/C/R/0 | E4: NTPC Renewable Energy Limited_KPS3 | F4: M/s. GUJARAT ALKALIES ANDCHEMICALS LIMITED -13032 | G4: 46026 | H4: 46026 | I4: 205.95 | J4: 205.95 | K4: 205.95 | O4: 80568 | P4: 5000 | Q4: 1000
A5: 154718 | B5: NVVN_Kreate_200MW | C5: SJVN010426WR2355 | D5: WR/2026/41026/C/R/0 | E5: NTPC Renewable Energy Limited_KPS3 | F5: M/s. GUJARAT ALKALIES ANDCHEMICALS LIMITED -13032 | G5: 46026 | H5: 46026 | I5: 7.8 | J5: 7.8 | K5: 7.8 | O5: 3051 | P5: 5000 | Q5: 1000
A6: 158826 | B6: NVVN_Kreate_200MW | C6: SJVN250426WR2356 | D6: WR/2026/42379/C/R/0 | E6: NTPC Renewable Energy Limited_KPS3 | F6: M/s. GUJARAT ALKALIES ANDCHEMICALS LIMITED -13032 | G6: 25/04/2026 | H6: 25/04/2026 | I6: 215.375 | J6: 215.375 | K6: 215.375 | O6: 84255 | P6: 5000 | Q6: 1000
A7: 159167 | B7: NVVN_Kreate_200MW | C7: SJVN260426WR2357 | D7: WR/2026/42484/C/R/0 | E7: NTPC Renewable Energy Limited_KPS3 | F7: ELECTROTHERM (INDIA) LIMITED | G7: 26/04/2026 | H7: 26/04/2026 | I7: 135 | J7: 135 | K7: 135 | O7: 52812 | P7: 5000 | Q7: 1000
A8: 159169 | B8: NVVN_Kreate_200MW | C8: SJVN260426WR2358 | D8: WR/2026/42485/C/R/0 | E8: NTPC Renewable Energy Limited_KPS3 | F8: M/s. GUJARAT ALKALIES ANDCHEMICALS LIMITED -13032 | G8: 26/04/2026 | H8: 26/04/2026 | I8: 111.925 | J8: 111.925 | K8: 111.925 | O8: 43785 | P8: 5000 | Q8: 1000
A9: 159369 | B9: NVVN_Kreate_200MW | C9: SJVN270426WR2359 | D9: WR/2026/42553/C/R/0 | E9: NTPC Renewable Energy Limited_KPS3 | F9: ELECTROTHERM (INDIA) LIMITED | G9: 27/04/2026 | H9: 27/04/2026 | I9: 133 | J9: 133 | K9: 133 | O9: 51886 | P9: 5000 | Q9: 1000
A10: 159370 | B10: NVVN_Kreate_200MW | C10: SJVN270426WR2360 | D10: WR/2026/42554/C/R/0 | E10: NTPC Renewable Energy Limited_KPS3 | F10: M/s. GUJARAT ALKALIES ANDCHEMICALS LIMITED -13032 | G10: 27/04/2026 | H10: 27/04/2026 | I10: 410 | J10: 410 | K10: 410 | O10: 159949 | P10: 5000 | Q10: 1000
A11: 159372 | B11: NVVN_Kreate_200MW | C11: SJVN270426WR2361 | D11: WR/2026/42555/C/R/0 | E11: NTPC Renewable Energy Limited_KPS3 | F11: M/s. GUJARAT ALKALIES ANDCHEMICALS LIMITED -13032 | G11: 27/04/2026 | H11: 27/04/2026 | I11: 47.5 | J11: 47.5 | K11: 47.5 | O11: 18531 | P11: 5000 | Q11: 1000
A12: 159661 | B12: NVVN_Kreate_200MW | C12: SJVN280426WR2362 | D12: WR/2026/42647/C/R/0 | E12: NTPC Renewable Energy Limited_KPS3 | F12: M/s. GUJARAT ALKALIES ANDCHEMICALS LIMITED -13032 | G12: 28/04/2026 | H12: 28/04/2026 | I12: 475 | J12: 475 | K12: 475 | O12: 185307 | P12: 5000 | Q12: 1000
A13: 159670 | B13: NVVN_Kreate_200MW | C13: SJVN280426WR2363 | D13: WR/2026/42649/C/R/0 | E13: NTPC Renewable Energy Limited_KPS3 | F13: M/s. GUJARAT ALKALIES ANDCHEMICALS LIMITED -13032 | G13: 28/04/2026 | H13: 28/04/2026 | I13: 47.5 | J13: 47.5 | K13: 47.5 | O13: 18531 | P13: 5000 | Q13: 1000
A14: 159676 | B14: NVVN_Kreate_200MW | C14: SJVN280426WR2364 | D14: WR/2026/42650/C/R/0 | E14: NTPC Renewable Energy Limited_KPS3 | F14: ELECTROTHERM (INDIA) LIMITED | G14: 28/04/2026 | H14: 28/04/2026 | I14: 133 | J14: 133 | K14: 133 | O14: 51886 | P14: 5000 | Q14: 1000
A15: 159943 | B15: NVVN_Kreate_200MW | C15: SJVN290426WR2366 | D15: WR/2026/42743/C/R/0 | E15: NTPC Renewable Energy Limited_KPS3 | F15: M/s. GUJARAT ALKALIES ANDCHEMICALS LIMITED -13032 | G15: 29/04/2026 | H15: 29/04/2026 | I15: 450 | J15: 450 | K15: 450 | O15: 175554 | P15: 5000 | Q15: 1000
A16: 159944 | B16: NVVN_Kreate_200MW | C16: SJVN290426WR2369 | D16: WR/2026/42744/C/R/0 | E16: NTPC Renewable Energy Limited_KPS3 | F16: M/s. GUJARAT ALKALIES ANDCHEMICALS LIMITED -13032 | G16: 29/04/2026 | H16: 29/04/2026 | I16: 45 | J16: 45 | K16: 45 | O16: 17555 | P16: 5000 | Q16: 1000
A17: 159946 | B17: NVVN_Kreate_200MW | C17: SJVN290426WR2370 | D17: WR/2026/42746/C/R/0 | E17: NTPC Renewable Energy Limited_KPS3 | F17: ELECTROTHERM (INDIA) LIMITED | G17: 29/04/2026 | H17: 29/04/2026 | I17: 135 | J17: 135 | K17: 135 | O17: 52666 | P17: 5000 | Q17: 1000
... A20: 160246 | B20: NVVN_Kreate_200MW | C20: SJVN300426WR2373 | D20: WR/2026/42851/C/R/0 | E20: NTPC Renewable Energy Limited_KPS3 | F20: ELECTROTHERM (INDIA) LIMITED | G20: 30/04/2026 | H20: 30/04/2026 | I20: 135 | J20: 135 | K20: 135 | O20: 52666 | P20: 5000 | Q20: 1000
E21: 46143
A22: 160469 | B22: NVVN_Kreate_200MW | C22: SJVN010526WR2374 | D22: WR/2026/42914/C/R/0 | E22: NTPC Renewable Energy Limited_KPS3 | F22: M/s. GUJARAT ALKALIES ANDCHEMICALS LIMITED -13032 | G22: 46027 | H22: 46027 | I22: 248.925 | J22: 248.925 | K22: 248.925 | O22: 97111 | P22: 5000 | Q22: 1000
A23: 160475 | B23: NVVN_Kreate_200MW | C23: SJVN010526WR2376 | D23: WR/2026/42916/C/R/0 | E23: NTPC Renewable Energy Limited_KPS3 | F23: M/s. GUJARAT ALKALIES ANDCHEMICALS LIMITED -13032 | G23: 46027 | H23: 46027 | I23: 45 | J23: 45 | K23: 45 | O23: 17555 | P23: 5000 | Q23: 1000
A24: 160478 | B24: NVVN_Kreate_200MW | C24: SJVN010526WR2377 | D24: WR/2026/42918/C/R/0 | E24: NTPC Renewable Energy Limited_KPS3 | F24: ELECTROTHERM (INDIA) LIMITED | G24: 46027 | H24: 46027 | I24: 117 | J24: 117 | K24: 117 | O24: 45644 | P24: 5000 | Q24: 1000
A25: 160482 | B25: NVVN_Kreate_200MW | C25: SJVN010526ER2378 | D25: ER/2026/28089/C/R/0 | E25: NTPC Renewable Energy Limited_KPS3 | F25: NUVOCO VISTAS CORPORATION LIMITED (Mejia Cement Plant) | G25: 46027 | H25: 46027 | I25: 20.25 | J25: 20.25 | K25: 20.25 | O25: 8485 | P25: 5000 | Q25: 1000
A26: 160789 | B26: NVVN_Kreate_200MW | C26: SJVN020526WR2380 | D26: WR/2026/43030/C/R/0 | E26: NTPC Renewable Energy Limited_KPS3 | F26: M/s. GUJARAT ALKALIES ANDCHEMICALS LIMITED -13032 | G26: 46058 | H26: 46058 | I26: 315.625 | J26: 315.625 | K26: 315.625 | O26: 123132 | P26: 5000 | Q26: 1000
A27: 160938 | B27: NVVN_Kreate_200MW | C27: SJVN030526WR2381 | D27: WR/2026/43078/C/R/0 | E27: NTPC Renewable Energy Limited_KPS3 | F27: M/s. GUJARAT ALKALIES ANDCHEMICALS LIMITED -13032 | G27: 46086 | H27: 46086 | I27: 340.475 | J27: 340.475 | K27: 340.475 | O27: 132826 | P27: 5000 | Q27: 1000
A28: 160940 | B28: NVVN_Kreate_200MW | C28: SJVN030526WR2382 | D28: WR/2026/43079/C/R/0 | E28: NTPC Renewable Energy Limited_KPS3 | F28: ELECTROTHERM (INDIA) LIMITED | G28: 46086 | H28: 46086 | I28: 130 | J28: 130 | K28: 130 | O28: 50716 | P28: 5000 | Q28: 1000
A29: 161092 | B29: NVVN_Kreate_200MW | C29: SJVN040526WR2383 | D29: WR/2026/43131/C/R/0 | E29: NTPC Renewable Energy Limited_KPS3 | F29: M/s. GUJARAT ALKALIES ANDCHEMICALS LIMITED -13032 | G29: 46117 | H29: 46117 | I29: 98.6 | J29: 98.6 | K29: 98.6 | O29: 38466 | P29: 5000 | Q29: 1000
A30: 161093 | B30: NVVN_Kreate_200MW | C30: SJVN040526WR2384 | D30: WR/2026/43132/C/R/0 | E30: NTPC Renewable Energy Limited_KPS3 | F30: ELECTROTHERM (INDIA) LIMITED | G30: 46117 | H30: 46117 | I30: 123.5 | J30: 123.5 | K30: 123.5 | O30: 48180 | P30: 5000 | Q30: 1000
A31: 161199 | B31: NVVN_Kreate_200MW | C31: SJVN050526WR2385 | D31: WR/2026/43164/C/R/0 | E31: NTPC Renewable Energy Limited_KPS3 | F31: M/s. GUJARAT ALKALIES ANDCHEMICALS LIMITED -13032 | G31: 46147 | H31: 46147 | I31: 113.6 | J31: 113.6 | K31: 113.6 | O31: 44318 | P31: 5000 | Q31: 1000
A32: 161204 | B32: NVVN_Kreate_200MW | C32: SJVN050526WR2386 | D32: WR/2026/43165/C/R/0 | E32: NTPC Renewable Energy Limited_KPS3 | F32: ELECTROTHERM (INDIA) LIMITED | G32: 46147 | H32: 46147 | I32: 126 | J32: 126 | K32: 126 | O32: 49155 | P32: 5000 | Q32: 1000
A33: 161344 | B33: NVVN_Kreate_200MW | C33: SJVN060526WR2387 | D33: WR/2026/43202/C/R/0 | E33: NTPC Renewable Energy Limited_KPS3 | F33: M/s. GUJARAT ALKALIES ANDCHEMICALS LIMITED -13032 | G33: 46178 | H33: 46178 | I33: 225.725 | J33: 225.725 | K33: 225.725 | O33: 88060 | P33: 5000 | Q33: 1000
... A39: 161693 | B39: NVVN_Kreate_200MW | C39: SJVN080526WR2393 | D39: WR/2026/43302/C/R/0 | E39: NTPC Renewable Energy Limited_KPS3 | F39: ELECTROTHERM (INDIA) LIMITED | G39: 46239 | H39: 46239 | I39: 115.5 | J39: 115.5 | K39: 115.5 | O39: 45059 | P39: 5000 | Q39: 1000
A40: GNA | B40: NVVN_Kreate_200MW | C40: SJVN080526NR2394 | D40: GNARE/WR/2026/05/08/9765 | E40: NTPC Renewable Energy Limited_KPS3 | F40: Himachal Pradesh State Electricity Board Ltd. | G40: 46239 | H40: 46239 | I40: 240 | J40: 240 | K40: 240 | O40: 0 | P40: 0 | Q40: 0
A41: 161874 | B41: NVVN_Kreate_200MW | C41: SJVN090526WR2395 | D41: WR/2026/43365/C/R/0 | E41: NTPC Renewable Energy Limited_KPS3 | F41: M/s. GUJARAT ALKALIES ANDCHEMICALS LIMITED -13032 | G41: 46270 | H41: 46270 | I41: 194.65 | J41: 194.65 | K41: 194.65 | O41: 75937 | P41: 5000 | Q41: 1000
A42: 161878 | B42: NVVN_Kreate_200MW | C42: SJVN090526WR2396 | D42: WR/2026/43367/C/R/0 | E42: NTPC Renewable Energy Limited_KPS3 | F42: Shreeyam Power And Steel Industries Limited, Mithirohar | G42: 46270 | H42: 46270 | I42: 31.5 | J42: 31.5 | K42: 31.5 | O42: 12289 | P42: 5000 | Q42: 1000
A43: 161880 | B43: NVVN_Kreate_200MW | C43: SJVN090526WR2397 | D43: WR/2026/43380/C/R/0 | E43: NTPC Renewable Energy Limited_KPS3 | F43: M/s Gujarat Alkalies & Chemicals Limited | G43: 46270 | H43: 46270 | I43: 90.6 | J43: 90.6 | K43: 90.6 | O43: 35345 | P43: 5000 | Q43: 1000
A44: 161884 | B44: NVVN_Kreate_200MW | C44: SJVN090526WR2398 | D44: WR/2026/43370/C/R/0 | E44: NTPC Renewable Energy Limited_KPS3 | F44: ELECTROTHERM (INDIA) LIMITED | G44: 46270 | H44: 46270 | I44: 105 | J44: 105 | K44: 105 | O44: 40963 | P44: 5000 | Q44: 1000
A45: GNA | B45: NVVN_Kreate_200MW | C45: SJVN090526NR2399 | D45: GNARE/WR/2026/05/09/8855 | E45: NTPC Renewable Energy Limited_KPS3 | F45: Himachal Pradesh State Electricity Board Ltd. | G45: 46270 | H45: 46270 | I45: 344.455 | J45: 344.455 | K45: 344.455 | O45: 0 | P45: 0 | Q45: 0
A46: GNA | B46: NVVN_Kreate_200MW | C46: SJVN100526NR2400 | D46: GNARE/WR/2026/05/10/4068 | E46: NTPC Renewable Energy Limited_KPS3 | F46: Himachal Pradesh State Electricity Board Ltd. | G46: 46300 | H46: 46300 | I46: 400 | J46: 400 | K46: 400 | O46: 0 | P46: 0 | Q46: 0
A47: 162023 | B47: NVVN_Kreate_200MW | C47: SJVN100526WR2404 | D47: WR/2026/43415/C/R/0 | E47: NTPC Renewable Energy Limited_KPS3 | F47: M/s. GUJARAT ALKALIES ANDCHEMICALS LIMITED -13032 | G47: 46300 | H47: 46300 | I47: 254.0375 | J47: 254.0375 | K47: 254.0375 | O47: 99105 | P47: 5000 | Q47: 1000
...

Sheet Daily Schedule
C1: NTPC VIDYUT VYAPAR NIGAM LIMITED & KREAT Energy India Pvt Ltd 200MW
B2: Date | C2: Availability (MWh) | D2: Kreate Requested (MWh) | E2: Actual Scheduled (MWh) | F2: Default from Kreate (MWh) | G2: Default from NVVN (MWh) | H2: Remark
B3: 46026 | C3: 2027.81 | D3: =Application_Ledger!J4+Application_Ledger!J5 -> 213.75 | E3: =Application_Ledger!K4+Application_Ledger!K5 -> 213.75 | F3: 0 | G3: =D3-E3 -> 0
B4: 25/04/2026 | C4: 2223.5 | D4: =Application_Ledger!J6 -> 215.375 | E4: =Application_Ledger!K6 -> 215.375 | F4: 0 | G4: =D4-E4 -> 0
B5: 26/04/2026 | C5: 2143.25 | D5: =Application_Ledger!J7+Application_Ledger!J8 -> 246.925 | E5: =Application_Ledger!K7+Application_Ledger!K8 -> 246.925 | F5: 0 | G5: =D5-E5 -> 0
B6: 27/04/2026 | C6: 2143.25 | D6: =Application_Ledger!J9+Application_Ledger!J10+Application_Ledger!J11 -> 590.5 | E6: =Application_Ledger!K9+Application_Ledger!K10+Application_Ledger!K11 -> 590.5 | F6: 0 | G6: =D6-E6 -> 0
B7: 28/04/2026 | C7: 2143.25 | D7: =Application_Ledger!J12+Application_Ledger!J13+Application_Ledger!J14 -> 655.5 | E7: =Application_Ledger!K12+Application_Ledger!K13+Application_Ledger!K14 -> 655.5 | F7: 0 | G7: =D7-E7 -> 0
B8: 29/04/2026 | C8: 2143.25 | D8: =Application_Ledger!J15+Application_Ledger!J16+Application_Ledger!J17 -> 630 | E8: =Application_Ledger!K15+Application_Ledger!K16+Application_Ledger!K17 -> 630 | F8: 0 | G8: =D8-E8 -> 0
B9: 30/04/2026 | C9: 2143.25 | D9: =Application_Ledger!J18+Application_Ledger!J19+Application_Ledger!J20 -> 539 | E9: =Application_Ledger!K18+Application_Ledger!K19+Application_Ledger!K20 -> 539 | F9: 0 | G9: =D9-E9 -> 0
B10: Monthly Total | C10: =SUM(C3:C9) -> 14967.56 | D10: =SUM(D3:D9) -> 3091.05 | E10: =SUM(E3:E9) -> 3091.05 | F10: =SUM(F3:F9) -> 0 | G10: =SUM(G3:G9) -> 0
B11: 46027 | C11: 2143.25 | D11: =Application_Ledger!J22+Application_Ledger!J23+Application_Ledger!J24+Application_Ledger!J25 -> 431.175 | E11: =Application_Ledger!K22+Application_Ledger!K23+Application_Ledger!K24+Application_Ledger!K25 -> 431.175 | F11: 0 | G11: =D11-E11 -> 0
B12: 46058 | C12: 2143.25 | D12: =Application_Ledger!J26 -> 315.625 | E12: =Application_Ledger!K26 -> 315.625 | F12: 0 | G12: =D12-E12 -> 0
B13: 46086 | C13: 2143.25 | D13: =Application_Ledger!J27+Application_Ledger!J28 -> 470.475 | E13: =Application_Ledger!K27+Application_Ledger!K28 -> 470.475 | F13: 0 | G13: =D13-E13 -> 0
B14: 46117 | C14: 2143.25 | D14: =Application_Ledger!J29+Application_Ledger!J30 -> 222.1 | E14: =Application_Ledger!K29+Application_Ledger!K30 -> 222.1 | F14: 0 | G14: =D14-E14 -> 0
B15: 46147 | C15: 2143.25 | D15: =Application_Ledger!J31+Application_Ledger!J32 -> 239.6 | E15: =Application_Ledger!K31+Application_Ledger!K32 -> 239.6 | F15: 0 | G15: =D15-E15 -> 0
B16: 46178 | C16: 2143.25 | D16: =Application_Ledger!J33+Application_Ledger!J34 -> 330.725 | E16: =Application_Ledger!K33+Application_Ledger!K34 -> 330.725 | F16: 0 | G16: =D16-E16 -> 0
B17: 46208 | C17: 2143.25 | D17: =Application_Ledger!J35+Application_Ledger!J36 -> 341.4 | E17: =Application_Ledger!K35+Application_Ledger!K36 -> 341.4 | F17: 0 | G17: =D17-E17 -> 0
B18: 46239 | C18: 2143.25 | D18: =Application_Ledger!J37+Application_Ledger!J38+Application_Ledger!J39+Application_Ledger!J40 -> 749.025 | E18: =Application_Ledger!K37+Application_Ledger!K38+Application_Ledger!K39+Application_Ledger!K40 -> 749.025 | F18: 0 | G18: =D18-E18 -> 0
B19: 46270 | C19: 2143.25 | D19: =sum(Application_Ledger!J41:J45) -> 766.205 | E19: =sum(Application_Ledger!K41:K45) -> 766.205 | F19: 0 | G19: =D19-E19 -> 0
B20: 46300 | C20: 2143.25 | D20: =Application_Ledger!J46+Application_Ledger!J47+Application_Ledger!J48+Application_Ledger!J49+Application_Ledger!J50 -> 916.5875 | E20: =Application_Ledger!K46+Application_Ledger!K47+Application_Ledger!K48+Application_Ledger!K49+Application_Ledger!K50 -> 916.5875 | F20: 0 | G20: =D20-E20 -> 0
B21: 46331 | C21: 2143.25 | D21: =Application_Ledger!J51+Application_Ledger!J52+Application_Ledger!J53+Application_Ledger!J54 -> 559.85 | E21: =Application_Ledger!K51+Application_Ledger!K52+Application_Ledger!K53+Application_Ledger!K54 -> 559.85 | F21: 0 | G21: =D21-E21 -> 0
B22: 46361 | C22: 2143.25 | D22: =Application_Ledger!J55+Application_Ledger!J56+Application_Ledger!J57+Application_Ledger!J58+Application_Ledger!J59 -> 692.65 | E22: =Application_Ledger!K55+Application_Ledger!K56+Application_Ledger!K57+Application_Ledger!K58+Application_Ledger!K59 -> 692.65 | F22: 0 | G22: =D22-E22 -> 0
B23: 13/05/2026 | C23: 2143.25 | D23: =sum(Application_Ledger!J60:J63) -> 494.7 | E23: =sum(Application_Ledger!K60:K63) -> 392.425 | F23: 0 | G23: =D23-E23 -> 102.275
B24: 14/05/2026 | C24: 2143.25 | D24: =sum(Application_Ledger!J64:J67) -> 416.4 | E24: =sum(Application_Ledger!K64:K67) -> 221.9 | F24: 0 | G24: =D24-E24 -> 194.5
B25: 15/05/2026 | C25: 2143.25 | D25: =sum(Application_Ledger!J68:J72) -> 376.975 | E25: =sum(Application_Ledger!K68:K72) -> 376.975 | F25: 0 | G25: =D25-E25 -> 0
B26: 16/05/2026 | C26: 2143.25 | D26: =Application_Ledger!J73+Application_Ledger!J74+Application_Ledger!J75+Application_Ledger!J76+Application_Ledger!J77 -> 314.85 | E26: =Application_Ledger!K73+Application_Ledger!K74+Application_Ledger!K75+Application_Ledger!K76+Application_Ledger!K77 -> 314.85 | F26: 0 | G26: =D26-E26 -> 0
B27: 17/05/2026 | C27: 2143.25 | D27: =Application_Ledger!J78+Application_Ledger!J79+Application_Ledger!J80+Application_Ledger!J81+Application_Ledger!J82 -> 409.6 | E27: =Application_Ledger!K78+Application_Ledger!K79+Application_Ledger!K80+Application_Ledger!K81+Application_Ledger!K82 -> 393.25 | F27: 0 | G27: =D27-E27 -> 16.35
B28: 18/05/2026 | C28: 2143.25 | D28: =Application_Ledger!K83+Application_Ledger!K84+Application_Ledger!K85+Application_Ledger!K86+Application_Ledger!K87 -> 435.975 | E28: =Application_Ledger!K83+Application_Ledger!K84+Application_Ledger!K85+Application_Ledger!K86+Application_Ledger!K87 -> 435.975 | F28: 0 | G28: =D28-E28 -> 0
B29: 19/05/2026 | C29: 2143.25 | D29: =Application_Ledger!J88+Application_Ledger!J89+Application_Ledger!J90+Application_Ledger!J91+Application_Ledger!J92 -> 374 | E29: =Application_Ledger!K88+Application_Ledger!K89+Application_Ledger!K90+Application_Ledger!K91+Application_Ledger!K92 -> 374 | F29: 0 | G29: =D29-E29 -> 0
B30: 20/05/2026 | C30: 2143.25 | D30: =Application_Ledger!J93+Application_Ledger!J94+Application_Ledger!J95+Application_Ledger!J96+14.8 -> 431 | E30: =Application_Ledger!K93+Application_Ledger!K94+Application_Ledger!K95+Application_Ledger!K96+14.8 -> 431 | F30: 0 | G30: =D30-E30 -> 0
B31: 21/05/2026 | C31: 2143.25 | D31: =Application_Ledger!J98+Application_Ledger!J99+Application_Ledger!J100+Application_Ledger!J101+Application_Ledger!J102+14.8 -> 732.075 | E31: =Application_Ledger!K98+Application_Ledger!K99+Application_Ledger!K100+Application_Ledger!K101+Application_Ledger!K102+14.8 -> 732.075 | F31: 0 | G31: =D31-E31 -> 0
B32: 22/05/2026 | C32: 2295.25 | D32: =Application_Ledger!J103+Application_Ledger!J104+Application_Ledger!J105+Application_Ledger!J106+Application_Ledger!J107+Application_Ledger!J108 -> 787.6 | E32: =Application_Ledger!K103+Application_Ledger!K104+Application_Ledger!K105+Application_Ledger!K106+Application_Ledger!K107+Application_Ledger!K108 -> 787.6 | F32: 0 | G32: =D32-E32 -> 0
B33: 23/05/2026 | C33: 2295.25 | D33: =Application_Ledger!J109+Application_Ledger!J110+Application_Ledger!J111+Application_Ledger!J112+Application_Ledger!J113+Application_Ledger!J114 -> 858.25 | E33: =Application_Ledger!K109+Application_Ledger!K110+Application_Ledger!K111+Application_Ledger!K112+Application_Ledger!K113+Application_Ledger!K114 -> 858.25 | F33: 0 | G33: =D33-E33 -> 0
B34: 24/05/2026 | C34: 2295.25 | D34: =Application_Ledger!J115+Application_Ledger!J116+Application_Ledger!J117+Application_Ledger!J118+Application_Ledger!J119+14.8 -> 902.3 | E34: =Application_Ledger!K115+Application_Ledger!K116+Application_Ledger!K117+Application_Ledger!K118+Application_Ledger!K119+14.8 -> 902.3 | F34: 0 | G34: =D34-E34 -> 0
B35: 25/05/2026 | C35: 2295.25 | D35: =Application_Ledger!J121+Application_Ledger!J122+Application_Ledger!J123+Application_Ledger!J124+Application_Ledger!J125+14.8 -> 849.4 | E35: =Application_Ledger!K121+Application_Ledger!K122+Application_Ledger!K123+Application_Ledger!K124+Application_Ledger!K125+14.8 -> 849.4 | F35: 0 | G35: =D35-E35 -> 0
B36: 26/05/2026 | C36: 2295.25 | D36: =Application_Ledger!J126+Application_Ledger!J127+Application_Ledger!J128+Application_Ledger!J129+Application_Ledger!J130+14.8 -> 661.075 | E36: =Application_Ledger!K126+Application_Ledger!K127+Application_Ledger!K128+Application_Ledger!K129+Application_Ledger!K130+14.8 -> 661.075 | F36: 0 | G36: =D36-E36 -> 0
B37: 27/05/2026 | C37: 2295.25 | D37: =Application_Ledger!J131+Application_Ledger!J132+Application_Ledger!J133+Application_Ledger!J134+Application_Ledger!J135+14.8 -> 614.725 | E37: =Application_Ledger!K131+Application_Ledger!K132+Application_Ledger!K133+Application_Ledger!K134+Application_Ledger!K135+14.8 -> 614.725 | F37: 0 | G37: =D37-E37 -> 0
B38: 28/05/2026 | C38: 2295.25 | D38: =Application_Ledger!J136+Application_Ledger!J137+Application_Ledger!J138+Application_Ledger!J139+Application_Ledger!J140+14.8 -> 619.2 | E38: =Application_Ledger!K136+Application_Ledger!K137+Application_Ledger!K138+Application_Ledger!K139+Application_Ledger!K140+14.8 -> 619.2 | F38: 0 | G38: =D38-E38 -> 0
B39: 29/05/2026 | C39: 2295.25 | D39: =Application_Ledger!J141+Application_Ledger!J142+Application_Ledger!J143+Application_Ledger!J144+14.8 -> 594.475 | E39: =Application_Ledger!K141+Application_Ledger!K142+Application_Ledger!K143+Application_Ledger!K144+14.8 -> 594.475 | F39: 0 | G39: =D39-E39 -> 0
B40: 30/05/2026 | C40: 2295.25 | D40: =Application_Ledger!J145+Application_Ledger!J146+Application_Ledger!J147+Application_Ledger!J148+Application_Ledger!J149+14.8 -> 671.725 | E40: =Application_Ledger!K145+Application_Ledger!K146+Application_Ledger!K147+Application_Ledger!K148+Application_Ledger!K149+14.8 -> 671.725 | F40: 0 | G40: =D40-E40 -> 0
...

Sheet Bills received
A1: Invoice Date | B1: Invoice No | C1: CSV | D1: Supply Period from | E1: Supply Period To | F1: Quantum of Power(MWH) | G1: Amount (Rs) | H1: Seller Name | I1: Due date | J1: Amount Paid (Rs.) | K1: Payment Date | L1: Remarks | M1: Net Value after TDS @ 0.1% | N1: TDS Payable | O1: Due Amount (Rs)
A2: 07.04.2026 | B2: 80013546 | C2: Vendor Payable Format 07.04.2026 | D2: 01.04.2026 | E2: 01.04.2026 | F2: 213.75 | G2: 671175 | H2: NTPCREL_PSS1_KPS3_S | I2: 08.04.2026 | J2: =G2-(0.1%*G2) -> 670503.82 | K2: 13.04.2026 | M2: =G2-(0.1%*G2) -> 670503.82 | N2: =G2*0.1% -> 671.175 | O2: =G2-J2-N2 -> 0
A3: 01.05.2026 | B3: 480013612 | C3: Vendor Payable Format 04.05.2026 | D3: 25.04.2026 | E3: 30.04.2026 | F3: 2877.3 | G3: 7897015 | H3: NTPCREL_PSS1_KPS3_S | I3: 02.05.2026 | J3: 7889118 | K3: 04.05.2026 | M3: =round(G3-(0.1%*G3),0) -> 7889118 | N3: =round(G3*0.1%,0) -> 7897 | O3: =G3-J3-N3 -> 0
A4: 09.05.2026 | B4: 480013646 | C4: Vendor Payable Format 10.05.2026 | D4: 01.05.2026 | E4: 08.05.2026 | F4: 3100.125 | G4: 4976090 | H4: NTPCREL_PSS1_KPS3_S | I4: 11.05.2026 | J4: 4971114 | K4: 11.05.2026 | M4: =round(G4-(0.1%*G4),0) -> 4971114 | N4: =round(G4*0.1%,0) -> 4976 | O4: =G4-J4-N4 -> 0
A5: 12.05.2026 | B5: 480013669 | C5: Vendor Payable Format 13.05.2026 | D5: 09.05.2026 | E5: 11.05.2026 | F5: 2242.643 | G5: 3882239 | H5: NTPCREL_PSS1_KPS3_S | I5: 13.05.2026 | J5: 3878357 | K5: 13.05.2026 | M5: =round(G5-(0.1%*G5),0) -> 3878357 | N5: =round(G5*0.1%,0) -> 3882 | O5: =G5-J5-N5 -> 0
A6: 18.05.2026 | B6: 480013690 | C6: Vendor Payable Format 19.05.2026 | D6: 12.05.2026 | E6: 17.05.2026 | F6: 2392.05 | G6: 5633871 | H6: NTPCREL_PSS1_KPS3_S | I6: 19.05.2026 | J6: 5628237 | K6: 19.05.2026 | M6: =round(G6-(0.1%*G6),0) -> 5628237 | N6: =round(G6*0.1%,0) -> 5634 | O6: =G6-J6-N6 -> 0
A7: 25.05.2026 | B7: 480013718 | C7: Vendor Payable Format 26.05.2026 | D7: 18.05.2026 | E7: 24.05.2026 | F7: 4521.2 | G7: 12755507 | H7: NTPCREL_PSS1_KPS3_S | I7: 26.05.2026 | J7: 12742751 | K7: 26.05.2026 | M7: =round(G7-(0.1%*G7),0) -> 12742751 | N7: =round(G7*0.1%,0) -> 12756 | O7: =G7-J7-N7 -> 0
A8: 01.06.2026 | B8: 480013719 | C8: Vendor Payable Format 01.05.2026 | D8: 25.05.2026 | E8: 31.05.2026 | F8: 4801 | G8: 12399840 | H8: NTPCREL_PSS1_KPS3_S | I8: 02.06.2026 | J8: 12387440 | K8: 02.06.2026 | M8: =round(G8-(0.1%*G8),0) -> 12387440 | N8: =round(G8*0.1%,0) -> 12400 | O8: =G8-J8-N8 -> 0
A9: 09.06.2026 | B9: 480013768 | C9: Vendor Payable Format 09.06.2026 | D9: 01.06.2026 | E9: 08.06.2026 | F9: 6528.543 | G9: 16492573 | H9: NTPCREL_PSS1_KPS3_S | I9: 10.06.2026 | J9: 16476080 | K9: 10.06.2026 | M9: =round(G9-(0.1%*G9),0) -> 16476080 | N9: =round(G9*0.1%,0) -> 16493 | O9: =G9-J9-N9 -> 0
A10: 16.06.2026 | B10: 480013792 | C10: Vendor Payable Format 16.06.2026 | D10: 09.06.2026 | E10: 15.06.2026 | F10: 6405.35 | G10: 13573911 | H10: NTPCREL_PSS1_KPS3_S | I10: 17.06.2026 | J10: 13560337 | K10: 19.06.2026 | M10: =round(G10-(0.1%*G10),0) -> 13560337 | N10: =round(G10*0.1%,0) -> 13574 | O10: =G10-J10-N10 -> 0
A11: 24.06.2026 | B11: 480013827 | C11: Vendor Payable Format 24.05.2026 | D11: 16.06.2026 | E11: 23.06.2026 | F11: 7864.075 | G11: 20824094 | H11: NTPCREL_PSS1_KPS3_S | I11: 25.06.2026 | J11: 20803270 | K11: 25.06.2026 | M11: =round(G11-(0.1%*G11),0) -> 20803270 | N11: =round(G11*0.1%,0) -> 20824 | O11: =G11-J11-N11 -> 0
A12: 01.07.2026 | B12: 480013878 | C12: Vendor Payable Format 01.07.2026 | D12: 24.06.2026 | E12: 30.06.2026 | F12: 8506 | G12: 20514075 | H12: NTPCREL_PSS1_KPS3_S | I12: 02.07.2026 | J12: 20493561 | K12: 02.07.2026 | M12: =round(G12-(0.1%*G12),0) -> 20493561 | N12: =round(G12*0.1%,0) -> 20514 | O12: =G12-J12-N12 -> 0

Sheet Bills issued by SJVN
A1: Invoice Date | B1: Invoice No | C1: Invoice Type | D1: Supply Period from | E1: Supply Period To | F1: Amount | G1: Party Name | H1: Payment Due date | I1: Payment Received | J1: Date of Payment | K1: Invoice after 0.1% TDS Deduction | L1: TDS Value @ 0.1% | M1: balance | N1: Remarks
A2: 04.05.2026 | B2: SJVN/ENERGY/KREATE/202605/144 | C2: Energy Bill | D2: 01.04.2026 | E2: 30.04.2026 | F2: 8660920 | G2: KREATE | H2: 05.05.2026 | I2: =8652189+5070 -> 8657259 | J2: Payment Recevied on next day of scheduling of power | K2: =ROUND(F2-(0.1%*F2),0) -> 8652259 | L2: =ROUND(F2*0.1%,0) -> 8661 | M2: =F2-I2-L2 -> -5000
A3: 04.05.2026 | B3: SJVN/OA/KREATE/202605/263 | C3: OA Bill | D3: 25.04.2026 | E3: 30.04.2026 | F3: 1212991 | G3: KREATE | H3: 05.05.2026 | I3: 1212991 | J3: 06.05.2026 | K3: 1212991 | L3: 0 | M3: =F3-I3-L3 -> 0
A4: 02.06.2026 | B4: SJVN/ENERGY/KREATE/202606/145 | C4: Energy Bill | D4: 01.05.2026 | E4: 31.05.2026 | F4: 40159255 | G4: KREATE | H4: 03.06.2026 | I4: 40119731 | J4: Payment Recevied on next day of scheduling of power | K4: =ROUND(F4-(0.1%*F4),0) -> 40119096 | L4: =ROUND(F4*0.1%,0) -> 40159 | M4: =F4-I4-L4 -> -635
A5: 11.05.2026 | B5: SJVN/OA/KREATE/202605/264 | C5: OA Bill | D5: 01.05.2026 | E5: 08.05.2026 | F5: 1224379 | G5: KREATE | H5: 12.05.2026 | I5: 1224379 | J5: 12.05.2026 | K5: 1224379 | L5: 0 | M5: =F5-I5-L5 -> 0
A6: 18.05.2026 | B6: SJVN/OA/KREATE/202605/265 | C6: OA Bill | D6: 09.05.2026 | E6: 15.05.2026 | F6: 1340100 | G6: KREATE | H6: 19.05.2026 | I6: 1340100 | J6: 19.05.2026 | K6: 1340100 | L6: 0 | M6: =F6-I6-L6 -> 0
A7: 27.05.2026 | B7: SJVN/OA/KREATE/202605/266 | C7: OA Bill | D7: 16.05.2026 | E7: 23.05.2026 | F7: 1961911 | G7: KREATE | H7: 28.05.2026 | I7: 1961911 | J7: 02.06.2026 | K7: 1961911 | L7: 0 | M7: =F7-I7-L7 -> 0
A8: 01.06.2026 | B8: SJVN/OA/KREATE/202606/267 | C8: OA Bill | D8: 24.05.2026 | E8: 31.05.2026 | F8: 2386581 | G8: KREATE | H8: 02.06.2026 | I8: 2386581 | J8: 03.06.2026 | K8: 2386581 | L8: 0 | M8: =F8-I8-L8 -> 0
A9: 04.06.2026 | B9: SJVN/OA/KREATE/202606/268 | C9: OA Bill | D9: 01.06.2026 | E9: 03.06.2026 | F9: 934820 | G9: KREATE | H9: 04.06.2026 | I9: 934820 | J9: Payment Recevied on Daily Basis | K9: 934820 | L9: 0 | M9: 0
A10: 01.07.2026 | B10: SJVN/ENERGY/KREATE/202607/146 | C10: Energy Bill | D10: 01.06.2026 | E10: 30.06.2026 | F10: 72283771 | G10: KREATE | H10: 02.07.2026 | I10: 72219123 | J10: Payment Recevied on next day of scheduling of power | K10: =ROUND(F10-(0.1%*F10),0) -> 72211487 | L10: =ROUND(F10*0.1%,0) -> 72284 | M10: =F10-I10-L10 -> -7636
A11: 01.07.2026 | B11: SJVN/OA/KREATE/202606/269 | C11: OA Bill | D11: 04.06.2026 | E11: 30.06.2026 | F11: 10708005 | G11: KREATE | H11: 02.07.2026 | I11: 10708005 | J11: Payment Recevied on Daily Basis | K11: 10708005 | L11: 0 | M11: 0

Sheet May TDS 2026
A1: Ref No | B1: Application No | C1: Approval No | D1: Party Name | E1: PAN | F1: Taxable Amount | G1: TDS Rate (%) | H1: TDS | I1: Remarks
A2: 160469 | B2: SJVN010526WR2374 | C2: WR/2026/42914/C/R/0 | D2: CTUIL | E2: AAJCC2026N | F2: 97111 | G2: 0.1 | H2: =ROUND(F2*G2,0) -> 9711 | I2: =F2-H2 -> 87400
A3: 160469 | B3: SJVN010526WR2374 | C3: WR/2026/42914/C/R/0 | D3: GRID-INDIA | E3: AAFCP2086B | F3: 5000 | G3: 0.1 | H3: =ROUND(F3*G3,0) -> 500 | I3: =F3-H3 -> 4500
A4: 160469 | B4: SJVN010526WR2374 | C4: WR/2026/42914/C/R/0 | D4: RLDC-Fee | E4: AAFCP2086B | F4: 1000 | G4: 0.1 | H4: =ROUND(F4*G4,0) -> 100 | I4: =F4-H4 -> 900
A5: 160475 | B5: SJVN010526WR2376 | C5: WR/2026/42916/C/R/0 | D5: CTUIL | E5: AAJCC2026N | F5: 17555 | G5: 0.1 | H5: =ROUND(F5*G5,0) -> 1756 | I5: =F5-H5 -> 15799
A6: 160475 | B6: SJVN010526WR2376 | C6: WR/2026/42916/C/R/0 | D6: GRID-INDIA | E6: AAFCP2086B | F6: 5000 | G6: 0.1 | H6: =ROUND(F6*G6,0) -> 500 | I6: =F6-H6 -> 4500
A7: 160475 | B7: SJVN010526WR2376 | C7: WR/2026/42916/C/R/0 | D7: RLDC-Fee | E7: AAFCP2086B | F7: 1000 | G7: 0.1 | H7: =ROUND(F7*G7,0) -> 100 | I7: =F7-H7 -> 900
A8: 160478 | B8: SJVN010526WR2377 | C8: WR/2026/42918/C/R/0 | D8: CTUIL | E8: AAJCC2026N | F8: 45644 | G8: 0.1 | H8: =ROUND(F8*G8,0) -> 4564 | I8: =F8-H8 -> 41080
A9: 160478 | B9: SJVN010526WR2377 | C9: WR/2026/42918/C/R/0 | D9: GRID-INDIA | E9: AAFCP2086B | F9: 5000 | G9: 0.1 | H9: =ROUND(F9*G9,0) -> 500 | I9: =F9-H9 -> 4500
A10: 160478 | B10: SJVN010526WR2377 | C10: WR/2026/42918/C/R/0 | D10: RLDC-Fee | E10: AAFCP2086B | F10: 1000 | G10: 0.1 | H10: =ROUND(F10*G10,0) -> 100 | I10: =F10-H10 -> 900
A11: 160482 | B11: SJVN010526ER2378 | C11: ER/2026/28089/C/R/0 | D11: CTUIL | E11: AAJCC2026N | F11: 8485 | G11: 0.1 | H11: =ROUND(F11*G11,0) -> 849 | I11: =F11-H11 -> 7636
A12: 160482 | B12: SJVN010526ER2378 | C12: ER/2026/28089/C/R/0 | D12: GRID-INDIA | E12: AAFCP2086B | F12: 5000 | G12: 0.1 | H12: =ROUND(F12*G12,0) -> 500 | I12: =F12-H12 -> 4500
A13: 160482 | B13: SJVN010526ER2378 | C13: ER/2026/28089/C/R/0 | D13: RLDC-Fee | E13: AAFCP2086B | F13: 1000 | G13: 0.1 | H13: =ROUND(F13*G13,0) -> 100 | I13: =F13-H13 -> 900
... A64: 161880 | B64: SJVN090526WR2397 | C64: WR/2026/43380/C/R/0 | D64: RLDC-Fee | E64: AAFCP2086B | F64: 1000 | G64: 0.1 | H64: =ROUND(F64*G64,0) -> 100 | I64: =F64-H64 -> 900
D65: CTUIL | E65: AAJCC2026N | G65: 0.1 | H65: =ROUND(F65*G65,0) -> 0 | I65: =F65-H65 -> 0
D66: GRID-INDIA | E66: AAFCP2086B | F66: 5000 | G66: 0.1 | H66: =ROUND(F66*G66,0) -> 500 | I66: =F66-H66 -> 4500
D67: RLDC-Fee | E67: AAFCP2086B | F67: 1000 | G67: 0.1 | H67: =ROUND(F67*G67,0) -> 100 | I67: =F67-H67 -> 900
D68: CTUIL | E68: AAJCC2026N | G68: 0.1 | H68: =ROUND(F68*G68,0) -> 0 | I68: =F68-H68 -> 0
D69: GRID-INDIA | E69: AAFCP2086B | F69: 5000 | G69: 0.1 | H69: =ROUND(F69*G69,0) -> 500 | I69: =F69-H69 -> 4500
D70: RLDC-Fee | E70: AAFCP2086B | F70: 1000 | G70: 0.1 | H70: =ROUND(F70*G70,0) -> 100 | I70: =F70-H70 -> 900
D71: CTUIL | E71: AAJCC2026N | G71: 0.1 | H71: =ROUND(F71*G71,0) -> 0 | I71: =F71-H71 -> 0
D72: GRID-INDIA | E72: AAFCP2086B | F72: 5000 | G72: 0.1 | H72: =ROUND(F72*G72,0) -> 500 | I72: =F72-H72 -> 4500
D73: RLDC-Fee | E73: AAFCP2086B | F73: 1000 | G73: 0.1 | H73: =ROUND(F73*G73,0) -> 100 | I73: =F73-H73 -> 900
D74: CTUIL | E74: AAJCC2026N | G74: 0.1 | H74: =ROUND(F74*G74,0) -> 0 | I74: =F74-H74 -> 0
D75: GRID-INDIA | E75: AAFCP2086B | F75: 5000 | G75: 0.1 | H75: =ROUND(F75*G75,0) -> 500 | I75: =F75-H75 -> 4500
D76: RLDC-Fee | E76: AAFCP2086B | F76: 1000 | G76: 0.1 | H76: =ROUND(F76*G76,0) -> 100 | I76: =F76-H76 -> 900
D77: CTUIL | E77: AAJCC2026N | G77: 0.1 | H77: =ROUND(F77*G77,0) -> 0 | I77: =F77-H77 -> 0
D78: GRID-INDIA | E78: AAFCP2086B | F78: 5000 | G78: 0.1 | H78: =ROUND(F78*G78,0) -> 500 | I78: =F78-H78 -> 4500
D79: RLDC-Fee | E79: AAFCP2086B | F79: 1000 | G79: 0.1 | H79: =ROUND(F79*G79,0) -> 100 | I79: =F79-H79 -> 900
D80: CTUIL | E80: AAJCC2026N | G80: 0.1 | H80: =ROUND(F80*G80,0) -> 0 | I80: =F80-H80 -> 0
D81: GRID-INDIA | E81: AAFCP2086B | F81: 5000 | G81: 0.1 | H81: =ROUND(F81*G81,0) -> 500 | I81: =F81-H81 -> 4500
D82: RLDC-Fee | E82: AAFCP2086B | F82: 1000 | G82: 0.1 | H82: =ROUND(F82*G82,0) -> 100 | I82: =F82-H82 -> 900
D83: CTUIL | E83: AAJCC2026N | G83: 0.1 | H83: =ROUND(F83*G83,0) -> 0 | I83: =F83-H83 -> 0
D84: GRID-INDIA | E84: AAFCP2086B | F84: 5000 | G84: 0.1 | H84: =ROUND(F84*G84,0) -> 500 | I84: =F84-H84 -> 4500
D85: RLDC-Fee | E85: AAFCP2086B | F85: 1000 | G85: 0.1 | H85: =ROUND(F85*G85,0) -> 100 | I85: =F85-H85 -> 900
D86: CTUIL | E86: AAJCC2026N | G86: 0.1 | H86: =ROUND(F86*G86,0) -> 0 | I86: =F86-H86 -> 0
D87: GRID-INDIA | E87: AAFCP2086B | F87: 5000 | G87: 0.1 | H87: =ROUND(F87*G87,0) -> 500 | I87: =F87-H87 -> 4500
D88: RLDC-Fee | E88: AAFCP2086B | F88: 1000 | G88: 0.1 | H88: =ROUND(F88*G88,0) -> 100 | I88: =F88-H88 -> 900

Sheet April TDS 2026
A1: Ref No | B1: Application No | C1: Approval No | D1: Party Name | E1: PAN | F1: Taxable Amount | G1: TDS Rate (%) | H1: TDS | I1: Remarks
A2: 154714 | B2: SJVN010426WR2354 | C2: WR/2026/41024/C/R/0 | D2: CTUIL | E2: AAJCC2026N | F2: 80568 | G2: 0.1 | H2: =ROUND(F2*G2,0) -> 8057 | I2: =F2-H2 -> 72511
A3: 154714 | B3: SJVN010426WR2354 | C3: WR/2026/41024/C/R/0 | D3: GRID-INDIA | E3: AAFCP2086B | F3: 5000 | G3: 0.1 | H3: =ROUND(F3*G3,0) -> 500 | I3: =F3-H3 -> 4500
A4: 154714 | B4: SJVN010426WR2354 | C4: WR/2026/41024/C/R/0 | D4: RLDC-Fee | E4: AAFCP2086B | F4: 1000 | G4: 0.1 | H4: =ROUND(F4*G4,0) -> 100 | I4: =F4-H4 -> 900
A5: 154718 | B5: SJVN010426WR2355 | C5: WR/2026/41026/C/R/0 | D5: CTUIL | E5: AAJCC2026N | F5: 3051 | G5: 0.1 | H5: =ROUND(F5*G5,0) -> 305 | I5: =F5-H5 -> 2746
A6: 154718 | B6: SJVN010426WR2355 | C6: WR/2026/41026/C/R/0 | D6: GRID-INDIA | E6: AAFCP2086B | F6: 5000 | G6: 0.1 | H6: =ROUND(F6*G6,0) -> 500 | I6: =F6-H6 -> 4500
A7: 154718 | B7: SJVN010426WR2355 | C7: WR/2026/41026/C/R/0 | D7: RLDC-Fee | E7: AAFCP2086B | F7: 1000 | G7: 0.1 | H7: =ROUND(F7*G7,0) -> 100 | I7: =F7-H7 -> 900
A8: 158826 | B8: SJVN250426WR2356 | C8: WR/2026/42379/C/R/0 | D8: CTUIL | E8: AAJCC2026N | F8: 84255 | G8: 0.1 | H8: =ROUND(F8*G8,0) -> 8426 | I8: =F8-H8 -> 75829
A9: 158826 | B9: SJVN250426WR2356 | C9: WR/2026/42379/C/R/0 | D9: GRID-INDIA | E9: AAFCP2086B | F9: 5000 | G9: 0.1 | H9: =ROUND(F9*G9,0) -> 500 | I9: =F9-H9 -> 4500
A10: 158826 | B10: SJVN250426WR2356 | C10: WR/2026/42379/C/R/0 | D10: RLDC-Fee | E10: AAFCP2086B | F10: 1000 | G10: 0.1 | H10: =ROUND(F10*G10,0) -> 100 | I10: =F10-H10 -> 900
A11: 159167 | B11: SJVN260426WR2357 | C11: WR/2026/42484/C/R/0 | D11: CTUIL | E11: AAJCC2026N | F11: 52812 | G11: 0.1 | H11: =ROUND(F11*G11,0) -> 5281 | I11: =F11-H11 -> 47531
A12: 159167 | B12: SJVN260426WR2357 | C12: WR/2026/42484/C/R/0 | D12: GRID-INDIA | E12: AAFCP2086B | F12: 5000 | G12: 0.1 | H12: =ROUND(F12*G12,0) -> 500 | I12: =F12-H12 -> 4500
A13: 159167 | B13: SJVN260426WR2357 | C13: WR/2026/42484/C/R/0 | D13: RLDC-Fee | E13: AAFCP2086B | F13: 1000 | G13: 0.1 | H13: =ROUND(F13*G13,0) -> 100 | I13: =F13-H13 -> 900
... A52: 160246 | B52: SJVN300426WR2373 | C52: WR/2026/42851/C/R/0 | D52: RLDC-Fee | E52: AAFCP2086B | F52: 1000 | G52: 0.1 | H52: =ROUND(F52*G52,0) -> 100 | I52: =F52-H52 -> 900

Sheet OPEN ACCESS PAYMENT AND APPROVE
A1: Delivary Date | B1: Application No | C1: Amount | E1: Payment Received
A2: 46028 | B2: SJVN010626WR2523 | C2: 118061 | E2: Received Date | F2: Amount Received
A3: 46028 | B3: SJVN010626WR2524 | C3: 102912 | E3: 46118 | F3: 324732
A4: 46028 | B4: SJVN010626WR2525 | C4: 18572
A5: 46028 | B5: SJVN010626WR2526 | C5: 48026
A6: 46028 | B6: SJVN010626WR2527 | C6: 37161
B7: Total | C7: 324732
A8: Delivary Date | B8: Application No | C8: Amount | E8: 46118 | F8: 337215
A9: 46059 | B9: SJVN020626WR2528 | C9: 125694
A10: 46059 | B10: SJVN020626WR2529 | C10: 109737
A11: 46059 | B11: SJVN020626WR2530 | C11: 18572
A12: 46059 | B12: SJVN020626WR2531 | C12: 41561
A13: 46059 | B13: SJVN020626WR2532 | C13: 41651
B14: Total | C14: 337215
A15: Delivary Date | B15: Application No | C15: Amount
A16: 46087 | B16: SJVN030626WR2534 | C16: 20727 | E16: 46118 | F16: 272873
A17: 46087 | B17: SJVN030626WR2535 | C17: 46500
A18: 46087 | B18: SJVN030626WR2536 | C18: 17225
A19: 46087 | B19: SJVN030626WR2537 | C19: 85509
A20: 46087 | B20: SJVN030626WR2538 | C20: 102912
B21: Total | C21: 272873
A22: Delivary Date | B22: Application No | C22: Amount
A23: 46118 | B23: SJVN040626WR2539 | C23: 107690 | E23: 46148 | F23: 338,051.00
A24: 46118 | B24: SJVN040626WR2540 | C24: 123279
A25: 46118 | B25: SJVN040626WR2541 | C25: 20368
A26: 46118 | B26: SJVN040626WR2542 | C26: 52696
A27: 46118 | B27: SJVN040626WR2543 | C27: 34018
B28: Total | C28: 338051
A29: Delivary Date | B29: Application No | C29: Amount
A30: 46148 | B30: SJVN050626WR2544 | C30: 107690 | E30: 46179 | F30: 308343
A31: 46148 | B31: SJVN050626WR2545 | C31: 123279
A32: 46148 | B32: SJVN050626WR2546 | C32: 49104
A33: 46148 | B33: SJVN050626WR2547 | C33: 28270
B34: Total | C34: 308343
A35: Delivary Date | B35: Application No | C35: Amount
A36: 46179 | B36: SJVN060626WR2548 | C36: 89790 | E36: 46240 | F36: 327530
A37: 46179 | B37: SJVN060626WR2549 | C37: 127050
A38: 46179 | B38: SJVN060626WR2550 | C38: 46949
A39: 46179 | B39: SJVN060626WR2551 | C39: 63741
B40: Total | C40: 327530
...

Sheet ENERGY PAYMENT 
A1: Sl. No | B1: Date | C1: Energy (KWh) | D1: Rate | E1: Amount | F1: TDS | G1: Cumulative Amount | H1: Payment made | I1: Payment date | J1: Payment due | K1: Bill No | L1: Bill date | M1: Energy | N1: Rate | O1: Amount | P1: TDS | Q1: TDS DEDUCTED | R1: Net Receivable | S1: Actual Receipt | T1: Difference | U1: Date of Receipt
A2: 46138
B3: 46026 | C3: 213750 | D3: 3.14 | E3: 671175 | F3: 6711.75 | G3: 664463.25 | M3: 213750 | N3: 3.17 | O3: 677587.5 | P3: 677.5875 | R3: 676909.91 | S3: 677587 | T3: 677.0875 | U3: 46269
B4: 25-04-2026 | C4: 215375 | D4: 2.956 | E4: 636649 | F4: 6366.49 | G4: 630282.51 | M4: 215375 | N4: 2.986 | O4: 643109.75 | P4: 643.10975 | R4: 642466.64 | S4: 642564 | T4: 97.35975 | U4: 27/04/2026
B5: 26-04-2026 | C5: 246925 | D5: 2.727 | E5: 673365 | F5: 6733.65 | G5: 666631.35 | M5: 246925 | N5: 2.757 | O5: 680772.23 | P5: 680.77223 | R5: 680091.46 | S5: 680214 | T5: 122.54223 | U5: 27/04/2026
B6: 27-04-2027 | C6: 590500 | D6: 2.688 | E6: 1587264 | F6: 15872.64 | G6: 1571391.4 | M6: 590500 | N6: 2.718 | O6: 1604979 | P6: 1604.979 | R6: 1603374 | S6: 1603590 | T6: 215.979 | U6: 27/04/2026
B7: 28-04-2026 | C7: 655500 | D7: 3.049 | E7: 1998620 | F7: 19986.2 | G7: 1978633.8 | M7: 655500 | N7: 3.079 | O7: 2018284.5 | P7: 2018.2845 | R7: 2016266.2 | S7: 2016103 | T7: -163.2155 | U7: 29-04-2026
B8: 29-04-2026 | C8: 630000 | D8: 2.588 | E8: 1630440 | F8: 16304.4 | G8: 1614135.6 | M8: 630000 | N8: 2.618 | O8: 1649340 | P8: 1649.34 | R8: 1647690.7 | S8: 1647840 | T8: 149.34 | U8: 30-04-2026
B9: 30-04-2026 | C9: 539000 | D9: 2.543 | E9: 1370677 | F9: 13706.77 | G9: 1356970.2 | M9: 539000 | N9: 2.573 | O9: 1386847 | P9: 1386.847 | R9: 1385460.2 | S9: 1384291 | T9: -1169.153 | U9: 46058
K10: Remaining amount for the supply of power for the month of april-26 & TDS is applicable above Rs. 5000000 | S10: 5070 | T10: 5070 | U10: 46178
B11: Total | C11: 3091050 | E11: 8568190 | F11: 85681.9 | G11: 8482508.1 | H11: 0 | I11: 0 | J11: 0 | M11: 3091050 | O11: 8660920 | P11: 8660.92 | R11: 8652259.1 | S11: 8652189 | T11: 4999.94
A12: 46168
A13: 1 | B13: 46027 | C13: 4,31,175 | D13: 1.913 | E13: 8,24,838.00 | F13: 825 | G13: 8,24,013.00 | K13: 1 | L13: 46027 | M13: 4,31,175 | N13: 1.943 | O13: 8,37,773.03 | P13: 837.77 | R13: 8,36,935.25 | S13: 8,37,138.00 | T13: 202.75 | U13: 46058
A14: 2 | B14: 46058 | C14: 3,15,625 | D14: 1.56 | E14: 4,92,375.00 | F14: 492 | G14: 4,91,883.00 | K14: 2 | L14: 46058 | M14: 3,15,625 | N14: 1.59 | O14: 5,01,843.75 | P14: 501.84 | R14: 5,01,341.91 | S14: 5,01,326.00 | T14: -15.91 | U14: 46117
A15: 3 | B15: 46086 | C15: 4,70,475 | D15: 1.205 | E15: 5,66,922.00 | F15: 567 | G15: 5,66,355.00 | K15: 3 | L15: 46086 | M15: 4,70,475 | N15: 1.235 | O15: 5,81,036.63 | P15: 581.04 | R15: 5,80,455.59 | S15: 5,80,662.00 | T15: 206.41 | U15: 46117
A16: 4 | B16: 46117 | C16: 2,22,100 | D16: 1.184 | E16: 2,62,966.00 | F16: 263 | G16: 2,62,703.00 | K16: 4 | L16: 46117 | M16: 2,22,100 | N16: 1.214 | O16: 2,69,629.40 | P16: 269.63 | R16: 2,69,359.77 | S16: 2,69,248.00 | T16: -111.77 | U16: 46147
A17: 5 | B17: 46147 | C17: 2,39,600 | D17: 1.53 | E17: 3,66,588.00 | F17: 367 | G17: 3,66,221.00 | K17: 5 | L17: 46147 | M17: 2,39,600 | N17: 1.56 | O17: 3,73,776.00 | P17: 373.78 | R17: 3,73,402.22 | S17: 3,73,515.00 | T17: 112.78 | U17: 46178
A18: 6 | B18: 46178 | C18: 3,30,725 | D18: 1.593 | E18: 5,26,845.00 | F18: 527 | G18: 5,26,318.00 | K18: 6 | L18: 46178 | M18: 3,30,725 | N18: 1.623 | O18: 5,36,766.68 | P18: 536.77 | R18: 5,36,229.91 | S18: 5,36,303.00 | T18: 73.09 | U18: 46208
A19: 7 | B19: 46208 | C19: 3,41,400 | D19: 1.83 | E19: 6,24,762.00 | F19: 625 | G19: 6,24,137.00 | K19: 7 | L19: 46208 | M19: 3,41,400 | N19: 1.86 | O19: 6,35,004.00 | P19: 635 | R19: 6,34,369.00 | S19: 6,34,288.00 | T19: -81 | U19: 46239
A20: 8 | B20: 46239 | C20: 7,49,025 | D20: 1.75 | E20: 13,10,794.00 | F20: 1311 | G20: 13,09,483.00 | K20: 8 | L20: 46239 | M20: 7,49,025 | N20: 1.78 | O20: 13,33,264.50 | P20: 1333.26 | R20: 13,31,931.24 | S20: 13,32,285.00 | T20: 353.76 | U20: 11.05.2026
A21: 9 | B21: 46270 | C21: 7,66,205 | D21: 1.989 | E21: 15,23,982.00 | F21: 1524 | G21: 15,22,458.00 | K21: 9 | L21: 46270 | M21: 7,66,205 | N21: 2.019 | O21: 15,46,967.90 | P21: 1546.97 | R21: 15,45,420.93 | S21: 15,45,083.00 | T21: -337.93 | U21: 11.05.2026
A22: 10 | B22: 46300 | C22: 9,16,588 | D22: 1.551 | E22: 14,21,628.00 | F22: 1422 | G22: 14,20,206.00 | K22: 10 | L22: 46300 | M22: 9,16,588 | N22: 1.581 | O22: 14,49,125.63 | P22: 1449.13 | R22: 14,47,676.50 | S22: 14,47,289.00 | T22: -387.5 | U22: 11.05.2026
A23: 11 | B23: 46331 | C23: 5,59,850 | D23: 1.673 | E23: 9,36,629.00 | F23: 937 | G23: 9,35,692.00 | K23: 11 | L23: 46331 | M23: 5,59,850 | N23: 1.703 | O23: 9,53,424.55 | P23: 953.42 | R23: 9,52,471.13 | S23: 9,52,591.00 | T23: 119.87 | U23: 12.05.2026
A24: 12 | B24: 46361 | C24: 6,92,650 | D24: 2.178 | E24: 15,08,592.00 | F24: 1509 | G24: 15,07,083.00 | K24: 12 | L24: 46361 | M24: 6,92,650 | N24: 2.208 | O24: 15,29,371.20 | P24: 1529.37 | R24: 15,27,841.83 | S24: 15,27,951.00 | T24: 109.17 | U24: 13.05.2026
A25: 13 | B25: 13-05-2026 | C25: 3,92,425 | D25: 2.208 | E25: 8,66,474.00 | F25: 866 | G25: 8,65,608.00 | K25: 13 | L25: 13-05-2026 | M25: 3,92,425 | N25: 2.238 | O25: 8,78,247.15 | P25: 878.25 | R25: 8,77,368.90 | S25: 8,77,480.00 | T25: 111.1 | U25: 14.05.2026
A26: 14 | B26: 14-05-2026 | C26: 2,21,900 | D26: 2.393 | E26: 5,31,007.00 | F26: 531 | G26: 5,30,476.00 | K26: 14 | L26: 14-05-2026 | M26: 2,21,900 | N26: 2.423 | O26: 5,37,663.70 | P26: 537.66 | R26: 5,37,126.04 | S26: 5,37,036.00 | T26: -90.04 | U26: 15.05.2026
A27: 15 | B27: 15-05-2026 | C27: 3,76,975 | D27: 2.56 | E27: 9,65,056.00 | F27: 965 | G27: 9,64,091.00 | K27: 15 | L27: 15-05-2026 | M27: 3,76,975 | N27: 2.59 | O27: 9,76,365.25 | P27: 976.37 | R27: 9,75,388.88 | S27: 9,75,553.00 | T27: 164.12 | U27: 16.05.2026
A28: 16 | B28: 16-05-2026 | C28: 3,14,850 | D28: 2.671 | E28: 8,40,964.00 | F28: 841 | G28: 8,40,123.00 | K28: 16 | L28: 16-05-2026 | M28: 3,14,850 | N28: 2.701 | O28: 8,50,409.85 | P28: 850.41 | R28: 8,49,559.44 | S28: 8,49,626.00 | T28: 66.56 | U28: 17.05.2026
A29: 17 | B29: 17-05-2026 | C29: 3,93,250 | D29: 2.344 | E29: 9,21,778.00 | F29: 922 | G29: 9,20,856.00 | K29: 17 | L29: 17-05-2026 | M29: 3,93,250 | N29: 2.374 | O29: 9,33,575.50 | P29: 933.58 | R29: 9,32,641.92 | S29: 9,32,657.00 | T29: 15.08 | U29: 17.05.2026
A30: 18 | B30: 18-05-2026 | C30: 4,35,975 | D30: 3.133 | E30: 13,65,910.00 | F30: 1366 | G30: 13,64,544.00 | K30: 18 | L30: 18-05-2026 | M30: 4,35,975 | N30: 3.163 | O30: 13,78,988.93 | P30: 1378.99 | R30: 13,77,609.94 | S30: 13,77,730.00 | T30: 120.06392 | U30: 19.05.2026
A31: 19 | B31: 19-05-2026 | C31: 3,74,000 | D31: 2.719 | E31: 10,16,906.00 | F31: 1017 | G31: 10,15,889.00 | K31: 19 | L31: 19-05-2026 | M31: 3,74,000 | N31: 2.749 | O31: 10,28,126.00 | P31: 1028.13 | R31: 10,27,097.87 | S31: 10,27,113.00 | T31: 15.126 | U31: 20-05-2027
A32: 20 | B32: 20-05-2026 | C32: 4,31,000 | D32: 2.693 | E32: 11,60,683.00 | F32: 1161 | G32: 11,59,522.00 | K32: 20 | L32: 20-05-2026 | M32: 4,31,000 | N32: 2.723 | O32: 11,73,613.00 | P32: 1173.61 | R32: 11,72,439.39 | S32: 11,72,299.00 | T32: -140.387 | U32: 21-05-2026
A33: 21 | B33: 21-05-2026 | C33: 7,32,075 | D33: 2.735 | E33: 20,02,225.00 | F33: 2002 | G33: 20,00,223.00 | K33: 21 | L33: 21-05-2026 | M33: 7,32,075 | N33: 2.765 | O33: 20,24,187.38 | P33: 2024.19 | R33: 20,22,163.19 | S33: 20,21,937.00 | T33: -226.18762 | U33: 22-05-2026
A34: 22 | B34: 22-05-2026 | C34: 7,87,600 | D34: 2.735 | E34: 21,54,086.00 | F34: 2154 | G34: 21,51,932.00 | K34: 22 | L34: 22-05-2026 | M34: 7,87,600 | N34: 2.765 | O34: 21,77,714.00 | P34: 2177.71 | R34: 21,75,536.29 | S34: 21,75,485.00 | T34: -51.286 | U34: 25-05-2026
A35: 23 | B35: 23-05-2026 | C35: 8,58,250 | D35: 3.111 | E35: 26,70,016.00 | F35: 2670 | G35: 26,67,346.00 | K35: 23 | L35: 23-05-2026 | M35: 8,58,250 | N35: 3.141 | O35: 26,95,763.25 | P35: 2695.76 | R35: 26,93,067.49 | S35: 26,93,128.00 | T35: 60.51325 | U35: 25-05-2026
A36: 24 | B36: 24-05-2026 | C36: 9,02,300 | D36: 2.644 | E36: 23,85,681.00 | F36: 2386 | G36: 23,83,295.00 | K36: 24 | L36: 24-05-2026 | M36: 9,02,300 | N36: 2.674 | O36: 24,12,750.20 | P36: 2412.75 | R36: 24,10,337.45 | S36: 24,10,371.00 | T36: 33.5502 | U36: 25-05-2026
... A43: 31 | B43: 31-05-2026 | C43: 7,90,400 | D43: 1.539 | E43: 12,16,426.00 | F43: 1216 | G43: 12,15,210.00 | K43: 31 | L43: 31-05-2026 | M43: 7,90,400 | N43: 1.569 | O43: 12,40,137.60 | P43: 1240.14 | R43: 12,38,897.46 | S43: 12,39,174.00 | T43: 276.5376 | U43: 01.05.2026
B44: Total | C44: 1,70,57,018.00 | E44: s | F44: 39649 | G44: ############ | H44: - | I44: - | J44: - | M44: 1,70,57,018.00 | O44: 4,01,59,255.67 | P44: 40159.26 | R44: 4,01,19,096.42 | S44: 4,01,19,731.00 | T44: 634.58
A45: 46168
A46: 1 | B46: 46028 | C46: 8,20,525 | D46: 1.974 | E46: 16,19,716.00 | F46: 1620 | G46: 16,18,096.00 | K46: 1 | L46: 46028 | M46: 8,20,525 | N46: 2.004 | O46: 16,44,332.10 | P46: 1644.33 | Q46: 1644 | R46: 16,42,687.77 | S46: 16,42,347.00 | T46: -340.7679 | U46: 46059
...

Sheet TDS
A1: Application date | B1: Appication No | C1: Vender name | E1: PAN | F1: Amount (Rs.) | G1: TDS amount Deducted by SJVN | H1: Total TDS amount | I1: Challan No | J1: Challan Date
A2: 45015 | C2: Delhi Transco Limited | D2: Delhi STU | E2: AABCD6342A | F2: 114762 | G2: =F2*0.1 -> 11476.2 | K2: =F2-G2 -> 103285.8
A3: 45015 | D3: West Bengal STU | E3: AAACW6952G | F3: 71520 | G3: =F3*0.1 -> 7152 | K3: =F3-G3 -> 64368
A4: 45027 | D4: Delhi STU | E4: AABCD6342A | F4: 54703 | G4: =F4*0.1 -> 5470.3 | H4: =G4+G5 -> 8879.4
A5: 45027 | D5: West Bengal STU | E5: AAACW6952G | F5: 34091 | G5: =F5*0.1 -> 3409.1
A6: 45028 | D6: Delhi STU | E6: AABCD6342A | F6: 57381 | G6: =F6*0.1 -> 5738.1 | H6: =G6+G7 -> 9314.1
A7: 45028 | D7: West Bengal STU | E7: AAACW6952G | F7: 35760 | G7: =F7*0.1 -> 3576
A10: 45029 | D10: Delhi STU | E10: AABCD6342A | F10: 57381 | G10: =F10*0.1 -> 5738.1 | H10: =G10+G11 -> 9314.1
A11: 45029 | D11: West Bengal STU | E11: AAACW6952G | F11: 35760 | G11: =F11*0.1 -> 3576
A13: 45030 | D13: Delhi STU | E13: AABCD6342A | F13: 57381 | G13: =F13*0.1 -> 5738.1 | H13: =G13+G14 -> 9314.1
A14: 45030 | D14: West Bengal STU | E14: AAACW6952G | F14: 35760 | G14: =F14*0.1 -> 3576
A16: 45031 | D16: Delhi STU | E16: AABCD6342A | F16: 57381 | G16: =F16*0.1 -> 5738.1 | H16: =G16+G17 -> 9314.1
A17: 45031 | D17: West Bengal STU | E17: AAACW6952G | F17: 35760 | G17: =F17*0.1 -> 3576
A19: 45032 | D19: Delhi STU | E19: AABCD6342A | F19: 57381 | G19: =F19*0.1 -> 5738.1 | H19: =G19+G20 -> 9314.1
A20: 45032 | D20: West Bengal STU | E20: AAACW6952G | F20: 35760 | G20: =F20*0.1 -> 3576
A23: 45033 | D23: Delhi STU | E23: AABCD6342A | F23: 57381 | G23: =F23*0.1 -> 5738.1 | H23: =G23+G24 -> 9314.1
A24: 45033 | D24: West Bengal STU | E24: AAACW6952G | F24: 35760 | G24: =F24*0.1 -> 3576
A27: 45034 | D27: Delhi STU | E27: AABCD6342A | F27: 57381 | G27: =F27*0.1 -> 5738.1 | H27: =G27+G28 -> 9314.1
A28: 45034 | D28: West Bengal STU | E28: AAACW6952G | F28: 35760 | G28: =F28*0.1 -> 3576
A31: 45035 | D31: Delhi STU | E31: AABCD6342A | F31: 57381 | G31: =F31*0.1 -> 5738.1 | H31: =G31+G32 -> 9314.1
A32: 45035 | D32: West Bengal STU | E32: AAACW6952G | F32: 35760 | G32: =F32*0.1 -> 3576
A35: 45036 | D35: Delhi STU | E35: AABCD6342A | F35: 76508 | G35: 7650.8 | H35: =G35+G36 -> 12418.8
A36: 45036 | D36: West Bengal STU | E36: AAACW6952G | F36: 47680 | G36: 4768

Sheet schedule
A1: Applicant | C1: SJVNL
A2: From State | C2: WEST BENGAL
A3: From Utility | C3: IPCL_WB
A4: To State | C4: DELHI
A5: To Utility | C5: NDMC
A6: IR Link | C6: East-North
A7: Appr. No | C7: NR/2023/11151/D
A8: Time Block | B8: Time Desc
A9: 1 | B9: 00:00-00:15 | C9: 0
A10: 2 | B10: 00:15-00:30 | C10: 0
A11: 3 | B11: 00:30-00:45 | C11: 0
A12: 4 | B12: 00:45-01:00 | C12: 0
A13: 5 | B13: 01:00-01:15 | C13: 0
A14: 6 | B14: 01:15-01:30 | C14: 0
A15: 7 | B15: 01:30-01:45 | C15: 0
A16: 8 | B16: 01:45-02:00 | C16: 0
A17: 9 | B17: 02:00-02:15 | C17: 0
A18: 10 | B18: 02:15-02:30 | C18: 0
A19: 11 | B19: 02:30-02:45 | C19: 0
A20: 12 | B20: 02:45-03:00 | C20: 0
... A104: 96 | B104: 23:45-24:00 | C104: 0
B105: MWHR | C105: =SUM(C9:C104)*15/60 -> 300
B106: Maximum | C106: =MAX(C9:C104) -> 40
B107: Minimum | C107: =MIN(C9:C104) -> 0
B108: Average | C108: =AVERAGE(C9:C104) -> 12.5

Sheet OA Bills
A2: Schedule of Payment
A4: From Date | B4: To Date | C4: SJVN App. No on NOAR | D4: NOAR Acceptance No | E4: Total Quantum (MWh) | F4: ISTS Charges | H4: STU Charges | J4: Operating Charges | O4: Total OA Charges
E5: MWH | F5: Injection | G5: Drawal | H5: West Bengal STU | I5: Delhi STU | J5: ERLDC | K5: NRLDC | L5: West Bengal -SLDC | M5: Delhi SLDC | N5: Application Fee on NOAR Portal | O5: Total OA Charges | P5: OA Charges to be born by Seller | Q5: OA Charges to be born by Buyer
F6: 0 | G6: 0 | H6: 238.4 | I6: 382.54 | J6: 1000 | K6: 1000 | L6: 1000 | M6: 1000 | N6: 5000
F7: Rs./Mwh | G7: Rs./Mwh | H7: Rs./Mwh | I7: Rs./Mwh | J7: Rs./ Day | K7: Rs./ Day | L7: Rs./ Day | M7: Rs./ Day
A8: 45016 | B8: 45016 | C8: SJVN/30032023 | D8: NR/2023/11151/D | E8: 300 | F8: =F$6*$E8 -> 0 | G8: =G$6*$E8 -> 0 | H8: =H$6*$E8 -> 71520 | I8: =I$6*$E8 -> 114762 | J8: =$J$6 -> 1000 | K8: =$K$6 -> 1000 | L8: =$L$6 -> 1000 | M8: =$M$6 -> 1000 | N8: =$N$6 -> 5000 | O8: =SUM(F8:N8) -> 195282 | P8: =N8+M8+K8+I8+G8 -> 121762 | Q8: =L8+J8+H8+F8 -> 73520
A9: 45234 | B9: 45234 | C9: =#REF! -> #REF! | D9: =#REF! -> #REF! | E9: =#REF! -> #REF! | F9: =F$6*$E9 -> #REF! | G9: =G$6*$E9 -> #REF! | H9: =H$6*$E9 -> #REF! | I9: =I$6*$E9 -> #REF! | J9: =$J$6 -> 1000 | K9: =$K$6 -> 1000 | L9: =$L$6 -> 1000 | M9: =$M$6 -> 1000 | N9: =$N$6 -> 5000 | O9: =SUM(F9:N9) -> #REF! | P9: =N9+M9+K9+I9+G9 -> #REF! | Q9: =L9+J9+H9+F9 -> #REF!
A10: =#REF! -> #REF! | B10: =#REF! -> #REF! | C10: =#REF! -> #REF! | D10: =#REF! -> #REF! | E10: =#REF! -> #REF! | F10: =F$6*$E10 -> #REF! | G10: =G$6*$E10 -> #REF! | H10: =H$6*$E10 -> #REF! | I10: =I$6*$E10 -> #REF! | J10: =J6 -> 1000 | K10: =K6 -> 1000 | L10: =L6 -> 1000 | M10: =M6 -> 1000 | N10: =N6 -> 5000 | O10: =SUM(F10:N10) -> #REF! | P10: =N10+M10+K10+I10+G10 -> #REF! | Q10: =L10+J10+H10+F10 -> #REF!

Sheet TDS to be paid
A1: Application Id | B1: Application No | C1: Approval No | D1: Name | E1: PAN | F1: TDS Deducted by SJVN | G1: Total Amount
A2: 38199 | B2: SJVN/2023-24/02/11042023 | C2: NR/2023/11468/D | D2: GRID-INDIA | E2: AAFCP2086B | F2: 0
A3: 38199 | B3: SJVN/2023-24/02/11042023 | C3: NR/2023/11468/D | D3: Delhi SLDC | E3: AABCD6342A | F3: 0
A4: 38199 | B4: SJVN/2023-24/02/11042023 | C4: NR/2023/11468/D | D4: West Bengal SLDC | E4: AAACW6952G | F4: 0
A5: 38199 | B5: SJVN/2023-24/02/11042023 | C5: NR/2023/11468/D | D5: Delhi STU | E5: AABCD6342A | F5: 5738 | G5: 57381
A6: 38199 | B6: SJVN/2023-24/02/11042023 | C6: NR/2023/11468/D | D6: West Bengal STU | E6: AAACW6952G | F6: 3576 | G6: 35760
A7: 38308 | B7: SJVN/2023-24/03/12042023 | C7: NR/2023/11494/C | D7: GRID-INDIA | E7: AAFCP2086B | F7: 0
A8: 38308 | B8: SJVN/2023-24/03/12042023 | C8: NR/2023/11494/C | D8: Delhi SLDC | E8: AABCD6342A | F8: 0
A9: 38308 | B9: SJVN/2023-24/03/12042023 | C9: NR/2023/11494/C | D9: West Bengal SLDC | E9: AAACW6952G | F9: 0
A10: 38308 | B10: SJVN/2023-24/03/12042023 | C10: NR/2023/11494/C | D10: Delhi STU | E10: AABCD6342A | F10: 5738 | G10: 57381
A11: 38308 | B11: SJVN/2023-24/03/12042023 | C11: NR/2023/11494/C | D11: West Bengal STU | E11: AAACW6952G | F11: 3576 | G11: 35760
A12: 38429 | B12: SJVN/2023-24/04/13042023 | C12: NR/2023/11522/C | D12: GRID-INDIA | E12: AAFCP2086B | F12: 0
A13: 38429 | B13: SJVN/2023-24/04/13042023 | C13: NR/2023/11522/C | D13: Delhi SLDC | E13: AABCD6342A | F13: 0
A14: 38429 | B14: SJVN/2023-24/04/13042023 | C14: NR/2023/11522/C | D14: West Bengal SLDC | E14: AAACW6952G | F14: 0
A15: 38429 | B15: SJVN/2023-24/04/13042023 | C15: NR/2023/11522/C | D15: Delhi STU | E15: AABCD6342A | F15: 5738 | G15: 57381
A16: 38429 | B16: SJVN/2023-24/04/13042023 | C16: NR/2023/11522/C | D16: West Bengal STU | E16: AAACW6952G | F16: 3576 | G16: 35760
A17: 38567 | B17: SJVN/2023-24/05/14042023 | C17: NR/2023/11547/C | D17: GRID-INDIA | E17: AAFCP2086B | F17: 0
A18: 38567 | B18: SJVN/2023-24/05/14042023 | C18: NR/2023/11547/C | D18: Delhi SLDC | E18: AABCD6342A | F18: 0
A19: 38567 | B19: SJVN/2023-24/05/14042023 | C19: NR/2023/11547/C | D19: West Bengal SLDC | E19: AAACW6952G | F19: 0
A20: 38567 | B20: SJVN/2023-24/05/14042023 | C20: NR/2023/11547/C | D20: Delhi STU | E20: AABCD6342A | F20: 5738 | G20: 57381
A21: 38567 | B21: SJVN/2023-24/05/14042023 | C21: NR/2023/11547/C | D21: West Bengal STU | E21: AAACW6952G | F21: 3576 | G21: 35760
A22: 39168 | B22: SJVN/2023-24/09/18042023 | C22: NR/2023/11678/C | D22: GRID-INDIA | E22: AAFCP2086B | F22: 200 | G22: 2000
A23: 39168 | B23: SJVN/2023-24/09/18042023 | C23: NR/2023/11678/C | D23: Delhi SLDC | E23: AABCD6342A | F23: 100 | G23: 1000
A24: 39168 | B24: SJVN/2023-24/09/18042023 | C24: NR/2023/11678/C | D24: West Bengal SLDC | E24: AAACW6952G | F24: 100 | G24: 1000
A25: 39168 | B25: SJVN/2023-24/09/18042023 | C25: NR/2023/11678/C | D25: Delhi STU | E25: AABCD6342A | F25: 5738 | G25: 57381
A26: 39168 | B26: SJVN/2023-24/09/18042023 | C26: NR/2023/11678/C | D26: West Bengal STU | E26: AAACW6952G | F26: 3576 | G26: 35760
A27: 39357 | B27: SJVN/2023-24/10/19042023 | C27: NR/2023/11720/C | D27: GRID-INDIA | E27: AAFCP2086B | F27: 700 | G27: 7000
A28: 39357 | B28: SJVN/2023-24/10/19042023 | C28: NR/2023/11720/C | D28: Delhi SLDC | E28: AABCD6342A | F28: 100 | G28: 1000
A29: 39357 | B29: SJVN/2023-24/10/19042023 | C29: NR/2023/11720/C | D29: West Bengal SLDC | E29: AAACW6952G | F29: 100 | G29: 1000
A30: 39357 | B30: SJVN/2023-24/10/19042023 | C30: NR/2023/11720/C | D30: Delhi STU | E30: AABCD6342A | F30: 7651 | G30: 76508
A31: 39357 | B31: SJVN/2023-24/10/19042023 | C31: NR/2023/11720/C | D31: West Bengal STU | E31: AAACW6952G | F31: 4768 | G31: 47680
A32: 38091 | B32: SJVN/2023-24/10042023 | C32: NR/2023/11443/C | D32: GRID-INDIA | E32: AAFCP2086B | F32: 0
A33: 38091 | B33: SJVN/2023-24/10042023 | C33: NR/2023/11443/C | D33: Delhi SLDC | E33: AABCD6342A | F33: 0
A34: 38091 | B34: SJVN/2023-24/10042023 | C34: NR/2023/11443/C | D34: West Bengal SLDC | E34: AAACW6952G | F34: 0
A35: 38091 | B35: SJVN/2023-24/10042023 | C35: NR/2023/11443/C | D35: Delhi STU | E35: AABCD6342A | F35: 5470 | G35: 54703
A36: 38091 | B36: SJVN/2023-24/10042023 | C36: NR/2023/11443/C | D36: West Bengal STU | E36: AAACW6952G | F36: 3409 | G36: 34091
A37: 39648 | B37: SJVN/2023-24/12/19042023 | C37: NR/2023/11771/D | D37: GRID-INDIA | E37: AAFCP2086B | F37: 700 | G37: 7000
A38: 39648 | B38: SJVN/2023-24/12/19042023 | C38: NR/2023/11771/D | D38: Delhi SLDC | E38: AABCD6342A | F38: 100 | G38: 1000
A39: 39648 | B39: SJVN/2023-24/12/19042023 | C39: NR/2023/11771/D | D39: West Bengal SLDC | E39: AAACW6952G | F39: 100 | G39: 1000
A40: 39648 | B40: SJVN/2023-24/12/19042023 | C40: NR/2023/11771/D | D40: Delhi STU | E40: AABCD6342A | F40: 7651 | G40: 76508
...

Sheet payment screenshot
A6: NDMC 1st Payment

Sheet pass
A1: url | B1: energx.iexindia.com
A2: iex participant ID | B2: N2DL0SJV000
A3: PASS | B3: Sjvniex@123
A6: url for pulse secure | B6: trading.iexindia.com

Sheet OA payments_NOAR
A1: ApplicationID | B1: ApplicationNo | C1: NetPayable | D1: PaidAmountFee | E1: PaidAmountFeeTds | F1: BilateralCharge | G1: BilateralTds | H1: Total | I1: TxAmountTotal | J1: Diff | K1: PaymentDueAmount | L1: PaymentStatus | M1: DueDate | N1: IsMigratedApp | O1: InterestCalculation | P1: Transactions
A2: 37017 | B2: SJVN/30032023 | C2: 195282 | D2: 5000 | E2: 0 | F2: 171654 | G2: 18628 | H2: 176654 | I2: 176654 | J2: 0 | K2: 0 | L2: Paid | M2: 45019.666 | N2: FALSE | O2: 0
A3: 38091 | B3: SJVN/2023-24/10042023 | C3: 97794 | D3: 5000 | E3: 0 | F3: 83915 | G3: 8879 | H3: 88915 | I3: 5000 | J3: -83915 | K3: 83915 | L3: Partially Paid | M3: 45029.692
A4: 38199 | B4: SJVN/2023-24/02/11042023 | C4: 102141 | D4: 5000 | E4: 0 | F4: 87827 | G4: 9314 | H4: 92827 | I4: 5000 | J4: -87827 | K4: 87827 | L4: Partially Paid | M4: 45030.536

Sheet Bill
D2: Energy Bill for 31 March 2023
A4: Sr. No | B4: Bill No | C4: Date | D4: Due Date | E4: Supplier | F4: Type of Energy | G4: Description | H4: Supply in kWh | I4: Rate (Rs.) | J4: Gross Amount (Rs.)
A5: 1 | B5: SJVN | C5: 45017 | D5: =C5+7 -> 45024 | E5: Kreate | F5: RE (Wind) | H5: 300000 | I5: 5.13 | J5: =I5*H5 -> 1539000
